Workbook

Sheet Automation Regression Test Plan
A1: Automation | B1: CR Related | C1: Test Case ID | D1: Priority | E1: Tester | F1: Category | G1: Account Type | H1: Product | I1: Test Case Description | J1: Test Case Steps | K1: Expected Result
A2: Not Automated | B2: 25 | C2: RT.1 | D2: High | F2: Personal | G2: Client Maintenance | I2: Document Manager | J2: 1. Search existing Client with DOB over 18, Tax ID type of "ATIN" and Tax ID number 2. Navigate to the Client Profile and choose Maintenance in Connects 3. Enter new name and validate popup a. Pop up displayed titled "Caution" b. Text displayed “Verify the customer’s ID. If non-identification documentation (e.g., divorce decree) is presented, upload through Document Access”. d. After OK, Message closed, user returned to window with focus on next available field 4. Update Address, Tax ID type/number and phone number | K2: 1. Validate TIN type and number are blanked out (ATIN only eligible for clients under 18 years of age)
A3: Not Automated | B3: 25 | C3: RT.2 | D3: High | F3: Personal | G3: Client Maintenance | I3: Document Manager | J3: 5. Navigate to Document Manager | K3: 1. Validate Customer Information Change form and W-9 generated with all fields mapped
A4: Not Automated | B4: 25 | C4: RT.3 | D4: High | F4: Personal | G4: Client Maintenance | I4: Client Profile - Connects | J4: 6. Validate Client and Account level (account that had address change) caution generated 7. End Session a. Choose OK on warning b. End Session again - validate session ends as normal. | K4: 1. Caution displays with text of "Address changed in last 31 days on related client, account or portfolio. Ensure you have identified the client properly." 2. Validate end session warning popup displays: a. Title = High Risk Change b. Text = "Changing the Address and E-Mail Address is considered High Risk. Ensure you have identified the client properly."
A5: Not Automated | B5: 25 | C5: RT.4 | D5: High | F5: Personal | G5: Client Maintenance | I5: Client Profile - Navigator | J5: 8. View client and account profile in Navigator | K5: 1. Validate name, address, TIN and phone number are the only fields that updated on the client record. a. Validate the primary phone mapped to both the field selected and the home phone field b. Validate Individual mapped to the Customer Type flex field 2. Validate address changed on selected account 3. Validate Caution did NOT map to client/Account level
A6: Not Automated | B6: 25 | C6: RT.5 | D6: High | F6: Personal | G6: Client Maintenance | I6: Client Profile - Maintenance Screen | J6: 1. Navigate to existing test customer with an existing alternate name and an employer of "Minor" that is over the age of 18 in Connects (must have last name of Customer) 2. Choose Pencil icon to maintenance the client record 3. Add a new alternate name to the client 4. Enter new valid Employer (not "Minor") 5. Complete all other required fields and save changes | K6: 1. Validate all fields on client record pulled in correctly into maintenance fields in Connects a. Exception: ID, Employer or Occupation containing Minor should be blanked out if the client's age is over 18. Validate Employer field is not populated.
A7: Not Automated | B7: 25 | C7: RT.6 | D7: High | F7: Personal | G7: Client Maintenance | I7: Document Manager | J7: 6. Navigate to Document Manager | K7: 1. Validate Customer Information Change form generated with all fields mapped
A8: Not Automated | B8: 25 | C8: RT.7 | D8: High | F8: Personal | G8: Client Maintenance | I8: Client Profile - Navigator | J8: 7. View client profile in Navigator | K8: 1. Validate new alternate name was added and existing alternate name was not removed 2. Validate "Individual" mapped to the Client Type flex field 3. Validate new Employer mapped as entered 4. Validate any other changed fields mapped
A9: Not Automated | B9: 25 | C9: RT.8 | D9: High | F9: Personal | G9: Client Maintenance | I9: Client Profile - Maintenance Screen | J9: 1. Navigate to existing test customer with an existing alternate name and an employer of "Minor" that is over the age of 18 in Connects (must have last name of Customer) 2. Choose Pencil icon to maintenance the client record 3. Change Country of Citizenship to a Non-US country a. Select No to Permanent Resident, Government-Issued Visas and Resident Alien for Tax Reporting questions 4. Add a new alternate name to the client 5. Enter new valid Employer (not "Minor") | K9: 1. Validate all fields on client record pulled in correctly into maintenance fields in Connects a. Exception: ID, Employer or Occupation containing Minor should be blanked out if the client's age is over 18. Validate Employer field is not populated.
A10: Not Automated | B10: 25 | C10: RT.9 | D10: High | F10: Personal | G10: Client Maintenance | I10: Document Manager | J10: 5. Navigate to Document Manager | K10: 1. Validate Customer Information Change form, W-9 and W-8 Ben generated with all fields mapped
A11: Not Automated | B11: 25 | C11: RT.10 | D11: High | F11: Personal | G11: Client Maintenance | I11: Client Profile - Navigator | J11: 6. View client profile in Navigator | K11: 1. Validate new alternate name was added and existing alternate name was not removed 2. Validate "Individual" mapped to the Client Type flex field 3. Validate new Employer mapped as entered 4. Validate new Country of Citizenship mapped to flex field
A12: Not Automated | B12: 25 | C12: RT.11 | D12: High | F12: Personal | G12: Client Maintenance | I12: Client Profile - Navigator | J12: 7. View client profile in Navigator and navigate to the Foreign Codes section | K12: 1. N maps to “U.S. Government Issued Visas?” flex field #33 in Nav 2. “N” maps to “Resident Alien for Tax Reporting” flex field #39 in Nav 3. “[1]” (Nonresident Alien High-Risk) displays in “Residency Status” field in Nav. 4. "N" maps to U.S. Permanent Resident Card flex field 5. "1042-S and W-8 Reporting" maps to "Foreign Code" field 6. "W-8 Beneficiary" maps to "W-8 Form Type" field 7. Current date maps to "Certification Date" host field 8. 3 years from the current date maps to the "Expiration Date" host field 9. "[29] Deposit Interest" maps to "Income Code" field 10. "[5] US Withholding Agent - FI" maps to "Chapter 3 Status Code" field 11. 2-digit country of citizenship abbreviation maps to "Country Residence Code" field 12. 2-digit country of citizenship abbreviation maps to "Country Tax Code" field 13. "Chapter 3 (NRA and Foreign Corporations)" maps to "Withholding Type' field
A13: Not Automated | B13: 35 | C13: RT.12 | D13: High | F13: Personal | G13: DDA | H13: Freestyle Checking | I13: Print TIS Only | J13: 1. Without a client in session, navigate to "Product Search" in Connects. 2. On a Freestyle checking account, select "Print TIS Only" 3. Validate a new Print window displays with the Freestyle Truth in Savings (not Document Manager) and print to PDF for testing purposes | K13: 1. Validate all mapping on the Freestyle Truth in Savings: a. Date Opened/As of = Curent Date b. Customer Name = For Informational Purposes Only c. Account Number = Blank d. Product = Freestyle checking e. Minimum Balance = blank or zero
A14: Not Automated | B14: 35 | C14: RT.13 | D14: High | F14: Personal | G14: DDA | H14: Health Savings - Individual Checking | I14: Print TIS Only | J14: 1. Without a client in session, navigate to "Product Search" in Connects. 2. On a Health Savings - Individual checking account, select "Print TIS Only" 3. Validate a new Print window displays with the Health Savings - Individual Truth in Savings (not Document Manager) and print to PDF for testing purposes | K14: 1. Validate all mapping on the Health Savings - Individual Truth in Savings: a. Date Opened/As of = current Date b. Customer Name = For Informational Purposes Only c. Account Number = Blank d. Product = Health Savings - Individual checking e.. Minimum Balance = blank or zero f. Rate and APY match to the current rate sheet for the region (APY rounded up to two decimal places)
A15: Not Automated | B15: 35 | C15: RT.14 | D15: High | F15: Personal | G15: DDA | H15: Firstrate Money Market Checking | I15: Print TIS Only | J15: 1. Without a client in session, navigate to "Product Search" in Connects. 2. On a Firstrate Money Market checking account, select "Print TIS Only" 3. Validate a new Print window displays with the Firstrate Money Market Truth in Savings (not Document Manager) and print to PDF for testing purposes | K15: 1. Validate all mapping on the Firstrate Money Market Truth in Savings: a. Date Opened/As of = current Date b. Customer Name = For Informational Purposes Only c. Account Number = Blank d. Product = Firstrate Money Market checking e. Rate and APY match to the current rate sheet for the region (APY rounded up to two decimal places)
A16: Not Automated | B16: 35 | C16: RT.15 | D16: High | F16: Personal | G16: SAV | H16: FirstRate Savings | I16: Print TIS Only | J16: 1. Without a client in session, navigate to "Product Search" in Connects. 2. On a FirstRate Savings account, select "Print TIS Only" 3. Validate a new Print window displays with the First Rate Savings Truth in Savings (not Document Manager) and print to PDF for testing purposes | K16: 1. Validate all mapping on the FirstRate Savings Truth in Savings: a. Date Opened/As of = Curent Date b. Customer Name = For Informational Purposes Only c. Account Number = Blank d. Product = FirstRate Savings e. Rate and APY match to the current rate sheet for the region (APY rounded up to two decimal places) f. Minimum Balance = blank or zero
A17: Not Automated | B17: 35 | C17: RT.16 | D17: High | F17: Personal | G17: SAV | H17: Saver's Goal CD | I17: Print TIS Only | J17: 1. Without a client in session, navigate to "Product Search" in Connects. 2. On a Saver's Goal CD account, select "Print TIS Only" 3. Validate a new Print window displays with the Regular CD Savings Truth in Savings (not Document Manager) and print to PDF for testing purposes | K17: 1. Validate all mapping on the Regular CD Truth in Savings: a. Date Opened/As of = current Date b. Customer Name = For Informational Purposes Only c. Account Number = Blank d. Product = Saver's Goal CD e. Issue Date = Blank f. Rate and APY match to the current rate sheet for the region (APY rounded up to two decimal places) g. "The minimum deposit to a Savers Goal CD is $25.00..." checkbox is selected h. "Automatically Renewable Time Account" checkbox selected
A18: Not Automated | B18: 35 | C18: RT.17 | D18: High | F18: Personal | G18: COD | H18: 18-23 MO CD | I18: Print TIS Only | J18: 1. Without a client in session, navigate to "Product Search" in Connects. 2. On a 18-23 MO CD account, select "Print TIS Only" 3. Validate a new Print window displays with the Regular CD Truth in Savings (not Document Manager) and print to PDF for testing purposes | K18: 1. Validate all mapping on the Regular CD Truth in Savings: a. Date Opened/As of = Curent Date b. Customer Name = For Informational Purposes Only c. Account Number = Blank d. Product = 18-23 MO CD e. Issue Date = Blank f. Rate and APY match to the current rate sheet for the region (APY rounded up to two decimal places) g. Minimum Balance = $500 (must be configured in CBRM as such) h. "You may not make any deposits into your account before maturity..." checkbox selected i. "Automatically Renewable Time Account" checkbox selected
A19: Not Automated | B19: 35 | C19: RT.18 | D19: High | F19: Personal | G19: COD | H19: 35 Month CD Special | I19: Print TIS Only | J19: 1. Without a client in session, navigate to "Product Search" in Connects. 2. On a 35 Month CD Special account, select "Print TIS Only" 3. Validate a new Print window displays with the Special CD Truth in Savings (not Document Manager) and print to PDF for testing purposes | K19: 1. Validate all mapping on the Special CD Truth in Savings: a. Date Opened/As of = Curent Date b. Customer Name = For Informational Purposes Only c. Account Number = Blank d. Product = 35 Month CD Special e. Issue Date = Blank f. Rate and APY match to the current rate sheet for the region (APY rounded up to two decimal places) g. Minimum Balance = $5,000 (must be configured in CBRM as such) h. Maximum Balance = $100,000 (must be configured in CBRM) i. "You may not make any deposits into your account before maturity..." checkbox selected j. "Automatically Renewable Time Account" checkbox selected
A20: Not Automated | B20: 35 | C20: RT.19 | D20: High | F20: Personal | G20: SAV | H20: IRA Savings | I20: Print TIS Only | J20: 1. Without a client in session, navigate to "Product Search" in Connects. 2. On a IRA Savings account, select "Print TIS Only" 3. Validate a new Print window displays with the IRA Savings Truth in Savings (not Document Manager) and print to PDF for testing purposes | K20: 1. Validate all mapping on the IRA Savings Truth in Savings: a. Date Opened/As of = current Date b. Customer Name = For Informational Purposes Only c. Account Number = Blank d. Product = IRA Savings e. Rate and APY match to the current rate sheet for the region (APY rounded up to two decimal places)
A21: Not Automated | B21: 35 | C21: RT.20 | D21: High | F21: Personal | G21: COD-IRA | H21: 6-11 MO IRA | I21: Print TIS Only | J21: 1. Without a client in session, navigate to "Product Search" in Connects. 2. On a 6-11 MO IRA account, select "Print TIS Only" 3. Validate a new Print window displays with the Regular CD Truth in Savings (not Document Manager) and print to PDF for testing purposes | K21: 1. Validate all mapping on the Regular CD Truth in Savings: a. Date Opened/As of = Curent Date b. Customer Name = For Informational Purposes Only c. Account Number = Blank d. Product = 6-11 MO IRA e. Issue Date = Blank f. Rate and APY match to the current rate sheet for the region (APY rounded up to two decimal places) g. Minimum Balance = $500 (must be configured in CBRM as such) h. "You may not make any deposits into your account before maturity..." checkbox selected i. "Automatically Renewable Time Account" checkbox selected
A22: Not Automated | B22: 35 | C22: RT.21 | D22: High | F22: Personal | G22: COD-IRA | H22: 7 MO IRA Special | I22: Print TIS Only | J22: 1. Without a client in session, navigate to "Product Search" in Connects. 2. On a 7 MO IRA Special account, select "Print TIS Only" 3. Validate a new Print window displays with the Special CD Truth in Savings (not Document Manager) and print to PDF for testing purposes | K22: 1. Validate all mapping on the Special CD Truth in Savings: a. Date Opened/As of = Curent Date b. Customer Name = For Informational Purposes Only c. Account Number = Blank d. Product = 7 MO IRA Special e. Issue Date = Blank f. Rate and APY match to the current rate sheet for the region (APY rounded up to two decimal places) g. Minimum Balance = $10,000 (must be configured in CBRM as such) h. Maximum Balance = $100,000 (must be configured in CBRM) i. "You may not make any deposits into your account before maturity..." checkbox selected j. "Automatically Renewable Time Account" checkbox selected
A23: Not Automated | B23: 35 | C23: RT.22 | D23: High | F23: Business | G23: COD | H23: 18-23 MO CD | I23: Print TIS Only | J23: 1. Without a client in session, navigate to "Product Search" in Connects and choose Business. 2. On a 18-23 MO CD account, select "Print TIS Only" 3. Validate a new Print window displays with the Regular CD Truth in Savings (not Document Manager) and print to PDF for testing purposes | K23: 1. Validate all mapping on the Regular CD Truth in Savings: a. Date Opened/As of = Curent Date b. Customer Name = For Informational Purposes Only c. Account Number = Blank d. Product = 18-23 MO CD e. Issue Date = Blank f. Rate and APY match to the current rate sheet for the region (APY rounded up to two decimal places) g. Minimum Balance = $500 (must be configured in CBRM as such) h. "You may not make any deposits into your account before maturity..." checkbox selected i. "Automatically Renewable Time Account" checkbox selected
A24: Not Automated | B24: 35 | C24: RT.23 | D24: High | F24: Business | G24: COD | H24: 35 Month CD Special | I24: Print TIS Only | J24: 1. Without a client in session, navigate to "Product Search" in Connects and choose Business. 2. On a 35 Month CD Special account, select "Print TIS Only" 3. Validate a new Print window displays with the Special CD Truth in Savings (not Document Manager) and print to PDF for testing purposes | K24: 1. Validate all mapping on the Special CD Truth in Savings: a. Date Opened/As of = Curent Date b. Customer Name = For Informational Purposes Only c. Account Number = Blank d. Product = 35 Month CD Special e. Issue Date = Blank f. Rate and APY match to the current rate sheet for the region (APY rounded up to two decimal places) g. Minimum Balance = $5,000 (must be configured in CBRM as such) h. Maximum Balance = $100,000 (must be configured in CBRM) i. "You may not make any deposits into your account before maturity..." checkbox selected j. "Automatically Renewable Time Account" checkbox selected
... A38: Not Automated | B38: 3 | C38: RT.37 | D38: Medium | F38: Stop Payment | G38: DDA | H38: Any Business | I38: FNB Bill Pay Stop Pay | J38: 1. Navigate to a test client Business DDA profile in Connects 2. Select FNB Bill Pay as the type | K38: 1. Validate helper text displays: "FNB Bill Stop Payment Request must be completed by FNB Customer Service. Please call Customer Service with the customer or direct them to the Customer Service line at : 1-800-555-5455" 3. Validate Stop Payment Agreement generated in Document Manager with all fields mapped a. Choose "Automatically Mail to Customer" for the Stop Pay Agreement, validate it archives in Director
A39: Not Automated | B39: 24/7 | C39: RT.38 | D39: High | F39: New Client_Personal | G39: Personal Client Setup | I39: Client Setup - US Citizen | J39: 1. Add New Client over 18 yrs/US Citizen 2. Complete Communication Preferences 3. Select "Residence" for address 4. Use the letters "PO" in address line 1 5. Choose a phone type other than "home" 6. Enter an email address 7. Use Driver's License as the ID type 8. Complete setup | K39: 1. Validate Residential address a. Country field of address window read only and disabled b. PO box not accepted as residence 2. Validate ChexSystems triggers and if response is Review or Decline, Supervisor Override is required a. Validate "N" is passed to "eStyle Eligible Only" flex field for client
A40: Not Automated | B40: 24 | C40: RT.39 | D40: High | F40: New Client_Personal | G40: Personal Client Setup | I40: Client Setup - US Citizen | J40: 9. View Client Profile in Navigator 10. In Connects, navigate to Document Manager | K40: 1. Validate data mapped to Navigator as entered: First Name Middle Name Last Name Suffix DOB Mailing Address Physical Address Primary Phone # entered w/no type maps to "home" in Nav Mobile phone Email address Tax ID Type Tax ID# Primary ID Type – Drivers Lisc State Issue Date Number Expiration Date Employer Occupation Individual maps to flex field 13 Current date maps to "Data Residency Question Answered" flex field 30 2. Validate no documents generated in Document Manager
A41: Not Automated | B41: 24/7 | C41: RT.40 | D41: High | F41: New Client_Personal | G41: Personal Client Setup | I41: Client Setup - Non-US Citizen | J41: 1. Create New Client: 2. Select Canada as the Country of Citizenship 3. N to Are you a Resident Alien for tax reporting purposes? 4. Enter Foreign Postal Code 5. Do not enter Foreign Tax ID 6. Select Canadian Province from DDLB 7. Select Canadian DL as ID Type 8. Complete Set Up | K41: 1. Tax Rate DDLB displayed under "Foreign Tax Identification Number" field 2. 0.00% only option available in Tax Rate DDLB 3. Foreign Postal Code is not required and displays under Tax Rate field 4. Foreign Tax Identification Number is not required and displays under Foreign Postal Code field 5. Canadian Province is required and displays under Foreign Tax Identification Number field 6. Validate ChexSystems triggers and if response is Review or Decline, Supervisor Override is required a. Validate "N" is passed to "eStyle Eligible Only" flex field for client
A42: Not Automated | B42: 24 | C42: RT.41 | D42: High | F42: New Client_Personal | G42: Personal Client Setup | I42: Client Setup - Non-US Citizen | J42: 9. View Client Profile in Navigator 10. In Connects, navigate to Document Manager | K42: 1. Validate data mapped to Navigator as entered: First Name Middle Name Last Name Suffix DOB Mailing Address Physical Address Primary Phone # entered w/no type maps to "home" in Nav Mobile phone Email address Tax ID Type Tax ID# Primary ID Type – Canadian DL Province Issue Date Number Expiration Date Employer Occupation Individual maps to flex field 13 Current date maps to "Data Residency Question Answered" flex field 30 2. 0% mapped to Tax Rate field 3. N maps to “U.S. Government Issued Visas?” flex field #33 in Nav 4. “Y” maps to “Resident Alien for Tax Reporting” flex field #39 in Nav 5. “[2]” (Resident Alien) displays in “Residency Status” field in Nav. 6. "N" maps to U.S. Permanent Resident Card flex field 7. [4] Exempt under tax treaty mapped to Exemption Code field 8. Foreign Postal Code maps to "Postal Code" field 9. Nothing maps to "Foreign Tax Identification Number" field 10. Canadian Province maps to "Province Code" field 11. "1042-S and W-8 Reporting" maps to "Foreign Code" field 12. "W-8 Beneficiary" maps to "W-8 Form Type" field 13. Current date maps to "Certification Date" host field 14. 3 years from the current date maps to the "Expiration Date" host field 15. "[29] Deposit Interest" maps to "Income Code" field 16. "[5] US Withholding Agent - FI" maps to "Chapter 3 Status Code" field 17. 2-digit country of citizenship abbreviation maps to "Country Residence Code" field 18. 2-digit country of citizenship abbreviation maps to "Country Tax Code" field 19. "Chapter 3 (NRA and Foreign Corporations)" maps to "Withholding Type' field 20. Validate W-9 and W-8 Ben generated in Document Manager with all fields mapped
A43: Not Automated | B43: 8 | C43: RT.42 | D43: Medium | F43: Quicksell | G43: Personal Client Setup | I43: Client Setup with Quicksell Offer | J43: 1. Create client with a pre-approved credit card offer 2. After creating, validate Product Search from LHN | K43: 1. Megaphone icon displayed next to "product search" option 2. When hovered over icon, tool tip "special offer" label displayed
A44: Not Automated | B44: 8 | C44: RT.43 | D44: Medium | F44: Quicksell | G44: Personal Client Setup | I44: Client Setup with Quicksell Offer | J44: 3. Open Product Search for client with offers 4. Select Setup, special offer should be the first product prompted 5. Select "offered" product, validate disclosure URL opens a. Select "Yes" button and validate message and special offer window close and the offer is removed from Product Selection Grid | K44: 1. Validate Special offer pop up display text 2. Product name displayed as returned in the ChexSystems response 3. Credit limit displayed as returned in the ChexSystems response 4. Rate displayed as returned in the ChexSystems response a. Display as “Prime + [Rate]%”
A45: Not Automated | B45: 8 | C45: RT.44 | D45: Medium | F45: Quicksell | G45: Personal Client Setup | I45: Client Setup with Quicksell Offer | J45: 6. Validate quicksell offer is in DWF queue for client | K45: 1. Right-click on form in Director, choose Keywords and validate the following keywords are mapped accurately: a. Tax ID Number = customers TIN with no spaces/dashes b. Reference Number = Alphanumeric offer code from Chexsystems with no spaces/dashes c. Miscellaneous Keyword 1 = "Y"
A46: Not Automated | B46: 8 | C46: RT.45 | D46: Medium | F46: Quicksell | G46: Personal Client Setup | I46: Client Setup with Quicksell Offer | J46: 7. Validate info written to Argo Database for client | K46: 1. Validate with Business Systems Analysis (Joe Renfro, Jason Miller, etc.) that the following info was written to the Offer_Disposition database: a. CIF # b. Accepted c. Offer Date
A47: Not Automated | B47: 8 | C47: RT.46 | D47: Medium | F47: Quicksell | G47: Personal Client Maintenance | I47: Client Maintenance with Quicksell Offer | J47: 1. Add new client with credit card offer to existing account 2. Complete account maintenance 3. Disposition ChexSystems offer by choosing Decline | K47: 1. Megaphone displays next to Product Selection Left-Hand Navigation 2. Maintenance allowed before offer dispositioned 3. Offer form archives to Director with N in Offer Accepted
A48: Not Automated | B48: 8 | C48: RT.47 | D48: Medium | F48: Quicksell | G48: Personal Client Maintenance | I48: Client Maintenance with Quicksell Offer | J48: 4. Validate quicksell offer is not in DWF queue | K48: 1. Right-click on form in Director, choose Keywords and validate the following keywords are mapped accurately: a. Tax ID Number = customers TIN with no spaces/dashes b. Reference Number = Alphanumeric offer code from Chexsystems with no spaces/dashes c. Miscellaneous Keyword 1 = "N"
A49: Not Automated | B49: 8 | C49: RT.48 | D49: Medium | F49: Quicksell | G49: Personal Client Maintenance | I49: Client Maintenance with Quicksell Offer | J49: 5. Validate info written to Argo Database | K49: 1. Validate with Business Systems Analysis (Joe Renfro, Jason Miller, etc.) that the following info was written to the Offer_Disposition database: a. CIF # b. Declined c. Offer Date
A50: Not Automated | B50: 8 | C50: RT.49 | D50: Medium | F50: Quicksell | G50: DDA | H50: Any Personal | I50: Account Setup | J50: 1. Use two clients with credit card offers that are not an owner or owner/signer on a DDA or SAV and add to a new account in a new session (ChexSystems must prompt when client is added to account) 2. Complete Account Setup 3. Attempt to end session 4. Navigate to product search and disposition both ChexSystems offers by choosing Accept | K50: a. Megaphone displays next to Product Selection Left-Hand Navigation b. Account Setup allowed before offer dispositioned c. Unable to end session without dispositioning offer i. At End Session, display a pop-up message with a disposition reminder 1. Title = “Special Offer Available” 2. Icon = Error 3. Text = “A special offer is available that needs to be dispositioned before closing the session.” 4. Button = “OK” a. When clicked closes pop-up message 5. Offer form archives to Director with Y in Offer Accepted
A51: Not Automated | B51: 8 | C51: RT.50 | D51: Medium | F51: Quicksell | G51: DDA | H51: Any Personal | I51: Account Setup | J51: 5. Validate quicksell offer is in DWF queue for both clients | K51: 1. Right-click on form in Director, choose Keywords and validate the following keywords are mapped accurately: a. Tax ID Number = customers TIN with no spaces/dashes b. Reference Number = Alphanumeric offer code from Chexsystems with no spaces/dashes c. Miscellaneous Keyword 1 = "Y"
A52: Not Automated | B52: 8 | C52: RT.51 | D52: Medium | F52: Quicksell | G52: DDA | H52: Any Personal | I52: Account Setup | J52: 6. Validate info written to Argo Database for each client | K52: 1. Validate with Business Systems Analysis (Joe Renfro, Jason Miller, etc.) that the following info was written to the Offer_Disposition database: a. CIF # b. Accepted c. Offer Date
A53: Not Automated | B53: 8 | C53: RT.52 | D53: Medium | F53: Quicksell | G53: SAV | H53: Any Personal | I53: Account Maintenance | J53: 1. Use client with credit card offer that is not an owner or owner/signer on a DDA or SAV and add to existing account in a new session (ChexSystems must prompt when client is added to account) 2. Complete account maintenance 3. Navigate to Product Search and disposition ChexSystems offer by choosing Decline | K53: 1. Megaphone displays next to Product Selection Left-Hand Navigation 2. Maintenance allowed before offer dispositioned 3. Offer form archives to Director with N in Offer Accepted
...

Sheet CR Automation Summary
A1: CR Related | B1: Automated | C1: Blocked | D1: Cancelled | E1: Not Automated | F1: Total
A2: 1 | B2: =COUNTIFS('Automation Regression Test Plan'!B:B,A2,'Automation Regression Test Plan'!A:A,"Automation") -> 0 | C2: =COUNTIFS('Automation Regression Test Plan'!B:B,A2,'Automation Regression Test Plan'!A:A,"Blocked") -> 0 | D2: =COUNTIFS('Automation Regression Test Plan'!B:B,A2,'Automation Regression Test Plan'!A:A,"Cancelled") -> 0 | E2: =COUNTIFS('Automation Regression Test Plan'!B:B,A2,'Automation Regression Test Plan'!A:A,"Not Automated") -> 10 | F2: 10
A3: 10 | B3: =COUNTIFS('Automation Regression Test Plan'!B:B,A3,'Automation Regression Test Plan'!A:A,"Automation") -> 0 | C3: =COUNTIFS('Automation Regression Test Plan'!B:B,A3,'Automation Regression Test Plan'!A:A,"Blocked") -> 0 | D3: =COUNTIFS('Automation Regression Test Plan'!B:B,A3,'Automation Regression Test Plan'!A:A,"Cancelled") -> 0 | E3: =COUNTIFS('Automation Regression Test Plan'!B:B,A3,'Automation Regression Test Plan'!A:A,"Not Automated") -> 70 | F3: 70
A4: 10/36 | B4: =COUNTIFS('Automation Regression Test Plan'!B:B,A4,'Automation Regression Test Plan'!A:A,"Automation") -> 0 | C4: =COUNTIFS('Automation Regression Test Plan'!B:B,A4,'Automation Regression Test Plan'!A:A,"Blocked") -> 0 | D4: =COUNTIFS('Automation Regression Test Plan'!B:B,A4,'Automation Regression Test Plan'!A:A,"Cancelled") -> 0 | E4: =COUNTIFS('Automation Regression Test Plan'!B:B,A4,'Automation Regression Test Plan'!A:A,"Not Automated") -> 1 | F4: 1
A5: 11 | B5: =COUNTIFS('Automation Regression Test Plan'!B:B,A5,'Automation Regression Test Plan'!A:A,"Automation") -> 0 | C5: =COUNTIFS('Automation Regression Test Plan'!B:B,A5,'Automation Regression Test Plan'!A:A,"Blocked") -> 0 | D5: =COUNTIFS('Automation Regression Test Plan'!B:B,A5,'Automation Regression Test Plan'!A:A,"Cancelled") -> 0 | E5: =COUNTIFS('Automation Regression Test Plan'!B:B,A5,'Automation Regression Test Plan'!A:A,"Not Automated") -> 8 | F5: 8
A6: 13 | B6: =COUNTIFS('Automation Regression Test Plan'!B:B,A6,'Automation Regression Test Plan'!A:A,"Automation") -> 0 | C6: =COUNTIFS('Automation Regression Test Plan'!B:B,A6,'Automation Regression Test Plan'!A:A,"Blocked") -> 0 | D6: =COUNTIFS('Automation Regression Test Plan'!B:B,A6,'Automation Regression Test Plan'!A:A,"Cancelled") -> 0 | E6: =COUNTIFS('Automation Regression Test Plan'!B:B,A6,'Automation Regression Test Plan'!A:A,"Not Automated") -> 13 | F6: 13
A7: 15 | B7: =COUNTIFS('Automation Regression Test Plan'!B:B,A7,'Automation Regression Test Plan'!A:A,"Automation") -> 0 | C7: =COUNTIFS('Automation Regression Test Plan'!B:B,A7,'Automation Regression Test Plan'!A:A,"Blocked") -> 0 | D7: =COUNTIFS('Automation Regression Test Plan'!B:B,A7,'Automation Regression Test Plan'!A:A,"Cancelled") -> 0 | E7: =COUNTIFS('Automation Regression Test Plan'!B:B,A7,'Automation Regression Test Plan'!A:A,"Not Automated") -> 4 | F7: 4
A8: 18 | B8: =COUNTIFS('Automation Regression Test Plan'!B:B,A8,'Automation Regression Test Plan'!A:A,"Automation") -> 0 | C8: =COUNTIFS('Automation Regression Test Plan'!B:B,A8,'Automation Regression Test Plan'!A:A,"Blocked") -> 0 | D8: =COUNTIFS('Automation Regression Test Plan'!B:B,A8,'Automation Regression Test Plan'!A:A,"Cancelled") -> 0 | E8: =COUNTIFS('Automation Regression Test Plan'!B:B,A8,'Automation Regression Test Plan'!A:A,"Not Automated") -> 9 | F8: 9
A9: 2 | B9: =COUNTIFS('Automation Regression Test Plan'!B:B,A9,'Automation Regression Test Plan'!A:A,"Automation") -> 0 | C9: =COUNTIFS('Automation Regression Test Plan'!B:B,A9,'Automation Regression Test Plan'!A:A,"Blocked") -> 0 | D9: =COUNTIFS('Automation Regression Test Plan'!B:B,A9,'Automation Regression Test Plan'!A:A,"Cancelled") -> 0 | E9: =COUNTIFS('Automation Regression Test Plan'!B:B,A9,'Automation Regression Test Plan'!A:A,"Not Automated") -> 1 | F9: 1
A10: 20 | B10: =COUNTIFS('Automation Regression Test Plan'!B:B,A10,'Automation Regression Test Plan'!A:A,"Automation") -> 0 | C10: =COUNTIFS('Automation Regression Test Plan'!B:B,A10,'Automation Regression Test Plan'!A:A,"Blocked") -> 0 | D10: =COUNTIFS('Automation Regression Test Plan'!B:B,A10,'Automation Regression Test Plan'!A:A,"Cancelled") -> 0 | E10: =COUNTIFS('Automation Regression Test Plan'!B:B,A10,'Automation Regression Test Plan'!A:A,"Not Automated") -> 53 | F10: 53
A11: 23 | B11: =COUNTIFS('Automation Regression Test Plan'!B:B,A11,'Automation Regression Test Plan'!A:A,"Automation") -> 0 | C11: =COUNTIFS('Automation Regression Test Plan'!B:B,A11,'Automation Regression Test Plan'!A:A,"Blocked") -> 0 | D11: =COUNTIFS('Automation Regression Test Plan'!B:B,A11,'Automation Regression Test Plan'!A:A,"Cancelled") -> 0 | E11: =COUNTIFS('Automation Regression Test Plan'!B:B,A11,'Automation Regression Test Plan'!A:A,"Not Automated") -> 25 | F11: 25
A12: 24 | B12: =COUNTIFS('Automation Regression Test Plan'!B:B,A12,'Automation Regression Test Plan'!A:A,"Automation") -> 0 | C12: =COUNTIFS('Automation Regression Test Plan'!B:B,A12,'Automation Regression Test Plan'!A:A,"Blocked") -> 0 | D12: =COUNTIFS('Automation Regression Test Plan'!B:B,A12,'Automation Regression Test Plan'!A:A,"Cancelled") -> 0 | E12: =COUNTIFS('Automation Regression Test Plan'!B:B,A12,'Automation Regression Test Plan'!A:A,"Not Automated") -> 2 | F12: 2
A13: 24/7 | B13: =COUNTIFS('Automation Regression Test Plan'!B:B,A13,'Automation Regression Test Plan'!A:A,"Automation") -> 0 | C13: =COUNTIFS('Automation Regression Test Plan'!B:B,A13,'Automation Regression Test Plan'!A:A,"Blocked") -> 0 | D13: =COUNTIFS('Automation Regression Test Plan'!B:B,A13,'Automation Regression Test Plan'!A:A,"Cancelled") -> 0 | E13: =COUNTIFS('Automation Regression Test Plan'!B:B,A13,'Automation Regression Test Plan'!A:A,"Not Automated") -> 2 | F13: 2
... A44: Product Search | B44: =COUNTIFS('Automation Regression Test Plan'!B:B,A44,'Automation Regression Test Plan'!A:A,"Automation") -> 0 | C44: =COUNTIFS('Automation Regression Test Plan'!B:B,A44,'Automation Regression Test Plan'!A:A,"Blocked") -> 0 | D44: =COUNTIFS('Automation Regression Test Plan'!B:B,A44,'Automation Regression Test Plan'!A:A,"Cancelled") -> 0 | E44: =COUNTIFS('Automation Regression Test Plan'!B:B,A44,'Automation Regression Test Plan'!A:A,"Not Automated") -> 10 | F44: 10
A45: Total Test Cases | B45: =SUBTOTAL(9,B2:B44) -> 1140 | C45: =SUBTOTAL(9,C2:C44) -> 33 | D45: =SUBTOTAL(9,D2:D44) -> 8 | E45: =SUBTOTAL(9,E2:E44) -> 1757 | F45: =SUBTOTAL(9,F2:F44) -> 2938
